Traceback (most recent call last):
  File "C:\Users\seidi\anaconda3\Lib\site-packages\nbclient\client.py", line 730, in _async_poll_for_reply
    msg = await ensure_async(self.kc.shell_channel.get_msg(timeout=new_timeout))
          ^^^^^^^^^^^^^^^^^^^^^^^^^^^^^^^^^^^^^^^^^^^^^^^^^^^^^^^^^^^^^^^^^^^^^^
  File "C:\Users\seidi\anaconda3\Lib\site-packages\nbclient\util.py", line 96, in ensure_async
    result = await obj
             ^^^^^^^^^
  File "C:\Users\seidi\anaconda3\Lib\site-packages\jupyter_client\channels.py", line 230, in get_msg
    raise Empty
_queue.Empty

During handling of the above exception, another exception occurred:

Traceback (most recent call last):
  File "C:\Users\seidi\anaconda3\Lib\site-packages\jupyter_cache\executors\utils.py", line 58, in single_nb_execution
    executenb(
  File "C:\Users\seidi\anaconda3\Lib\site-packages\nbclient\client.py", line 1204, in execute
    return NotebookClient(nb=nb, resources=resources, km=km, **kwargs).execute()
           ^^^^^^^^^^^^^^^^^^^^^^^^^^^^^^^^^^^^^^^^^^^^^^^^^^^^^^^^^^^^^^^^^^^^^
  File "C:\Users\seidi\anaconda3\Lib\site-packages\nbclient\util.py", line 84, in wrapped
    return just_run(coro(*args, **kwargs))
           ^^^^^^^^^^^^^^^^^^^^^^^^^^^^^^^
  File "C:\Users\seidi\anaconda3\Lib\site-packages\nbclient\util.py", line 62, in just_run
    return loop.run_until_complete(coro)
           ^^^^^^^^^^^^^^^^^^^^^^^^^^^^^
  File "C:\Users\seidi\anaconda3\Lib\asyncio\base_events.py", line 653, in run_until_complete
    return future.result()
           ^^^^^^^^^^^^^^^
  File "C:\Users\seidi\anaconda3\Lib\site-packages\nbclient\client.py", line 663, in async_execute
    await self.async_execute_cell(
  File "C:\Users\seidi\anaconda3\Lib\site-packages\nbclient\client.py", line 949, in async_execute_cell
    exec_reply = await self.task_poll_for_reply
                 ^^^^^^^^^^^^^^^^^^^^^^^^^^^^^^
  File "C:\Users\seidi\anaconda3\Lib\site-packages\nbclient\client.py", line 754, in _async_poll_for_reply
    await self._async_handle_timeout(timeout, cell)
  File "C:\Users\seidi\anaconda3\Lib\site-packages\nbclient\client.py", line 801, in _async_handle_timeout
    raise CellTimeoutError.error_from_timeout_and_cell(
nbclient.exceptions.CellTimeoutError: A cell timed out while it was being executed, after 30 seconds.
The message was: Cell execution timed out.
Here is a preview of the cell contents:
-------------------
['# Bibliotecas que já conhecemos', 'import pandas as pd             # Trabalho com dados tabulares', 'import matplotlib.pyplot as plt # Visualização de figuras e manipulação do tamanho e disposição delas', 'import seaborn as sns           # API sobre o matplotlib, que facilita a criação e customização das figuras', 'import numpy as np              # Operações numéricas entre vetores, matrizes, etc']
...
['# Biblioteca nova, para a geração de modelos de predição', 'from sklearn.preprocessing   import RobustScaler        # para auxiliar a regressão logística', 'from sklearn.model_selection import train_test_split    # separação entre base de treino e de teste', 'from sklearn.linear_model    import LinearRegression    # modelo que vamos usar', 'from sklearn.linear_model    import LogisticRegression  # segundo modelo que usaremos']
-------------------

